# Async Functions

- [Async Functions](#async-functions)
	- [Intro](#intro)
	- [`return` vs. `await` vs. `return await`](#return-vs-await-vs-return-await)
	- [Practice](#practice)
		- [Simultanious and Consecutive timeouts](#simultanious-and-consecutive-timeouts)
		- [Parallel and Consecutive scripts loading](#parallel-and-consecutive-scripts-loading)
		- [The github avatars task using `async/await`](#the-github-avatars-task-using-asyncawait)
		- [https://learn.javascript.ru/async-await#perepishite-ispolzuya-async-await](#httpslearnjavascriptruasync-awaitperepishite-ispolzuya-async-await)
		- [https://learn.javascript.ru/async-await#perepishite-ispolzuya-async-await](#httpslearnjavascriptruasync-awaitperepishite-ispolzuya-async-await-1)

## Intro

`async` functions return `promise` (any primitives are converted to resolved promise). 

```javascript
async function f(){
	return Promise.resolve(1)
}

// is the same as 

async function f(){
	return 1
}

f() 						// PromiseÂ {<resolved>: 1}
.then(r => console.log(r))	// 1
```
***

The `await` keyword makes the engine to wait for the promise on the right to be fulfilled. Then it'll return its result and the execution will continue. 

**NB**: `await` should not be used in the global scope. It only works when pasting code in DevTools but this **will not** work in regular script files! And even in DevTools it can cause unexpected errors (like functions refuse to hoist).

```javascript
async function f(){
	const promise = new Promise((res, rej) => {
		setTimeout(() => res('ok'), 1000)
	})

	const result = await promise

	console.log(result)

	return result
}

f()		// logs 'ok' in 1 s
```
So, besically we use `await` instead of `.then`, just use them before the promises, not after. 
***

We can create async `class` methods with no problem.

```javascript
class Waiter {
	async wait(){
		return await Promise.resolve(1)
	}
}

new Waiter().wait()
.then(console.log)	// 1
```
***


## `return` vs. `await` vs. `return await`

What should we use? To be short: outside of `try/catch` never use `return await` - it's redundant. Just `return` what you need. But in `try/catch` you may use `return await` to catch errors effectively. Details with examples: 

```javascript
async function waitAndMaybeReject() {
	// Wait one second
	await new Promise(r => setTimeout(r, 1000))
	// Toss a coin
	const isHeads = Boolean(Math.round(Math.random()))

	if (isHeads) return 'yay'
	throw Error('Boo!')
}

async function foo() {
	try {
		waitAndMaybeReject()
	} catch (e) {
		return 'caught'
	}
}

foo().then(res => console.log(res))
// always `undefined` and half time also throws `Uncaught Error`
```

Here, if you call `foo()`, the returned **promise** will always fulfill with `undefined`, without waiting.

Since we don't await or return the result of `waitAndMaybeReject()`, we don't react to it in any way. Code like this is usually a mistake.

```javascript
async function foo() {
	try {
		await waitAndMaybeReject()
	} catch (e) {
		return 'caught'
	}
}

foo().then(res => console.log(res))
// half time `undefined`, half time `caught`
```
Here, if you call `foo()`, the returned promise will always wait one second, then either fulfill with `undefined`, or fulfill with `"caught"`.

Because we `await` the result of `waitAndMaybeReject()`, its **rejection will be turned into a throw**, and our `catch` block will execute. However, if `waitAndMaybeReject()` fulfills, we don't do anything with the value.

```javascript
async function foo() {
	try {
		return waitAndMaybeReject()
	} catch (e) {
		return 'caught'
	}
}

foo().then(res => console.log(res))
// half time `yay`, half time `Uncaught Error`
```

Here, if you call `foo()`, the returned promise will always wait one second, then either `fulfill` with "yay", or `reject` with Error('Boo!').

By returning `waitAndMaybeReject()`, we're **deferring** to its result, so our **`catch` block never runs**.

```javascript
async function foo() {
	try {
		return await waitAndMaybeReject()
	} catch (e) {
		return 'caught'
	}
}

foo().then(res => console.log(res))
// half time `yay`, half time `caught`
```

Here, if you call `foo()`, the returned promise will always wait one second, then either `fulfill` with "yay", or `fulfill` with "caught".

Because we await the result of `waitAndMaybeReject()`, its **rejection will be turned into a throw**, and our `catch` block will execute. If waitAndMaybeReject() fulfills, we return its result.

If the above seems confusing, it might be easier to think of it as two separate steps:

```javascript
async function foo() {
  try {
    // Wait for the result of waitAndMaybeReject() to settle,
    // and assign the fulfilled value to fulfilledValue:
    const fulfilledValue = await waitAndMaybeReject();
    // If the result of waitAndMaybeReject() rejects, our code
    // throws, and we jump to the catch block.
    // Otherwise, this block continues to run:
    return fulfilledValue;
  }
  catch (e) {
    return 'caught';
  }
}
```

If you didn't await for async error in `try`, it will just finish working and when error finally fires, you'll get unhandled error. Thus, **if you want to `tru..catch` async errors, always `await` for them!** 

***


## Practice

### Simultanious and Consecutive timeouts

The only difference is: we should `await` for every `async` function call if we want consecutive executions, otherwise - don't (and they will trigger one after another returning ticking promises, and timeouts will collapse into each other).

```javascript
const delays = [2000, 3000, 1000]

async function delay(ms){
	return new Promise(resolve => setTimeout(() => {	// we can also 'await' here instead of `return`
		resolve(ms)
	}, ms))
}

for(const value of delays){		// [].map doesn't work here!
	await delay(value)		// <--- remove this `await` to make the function calls simultanious
	.then(result => console.log(result))
}
```
***


### Parallel and Consecutive scripts loading

The importang thing to understand: the script loading function **is always the same**. We only change the way we call it from the outside: 

1. If we loop to call the `loadScript` without awaiting, all the promises will start executing almost simultaniously. In this case we only need to add them to the array and `Promise.all` for all of them to fulfill. 
2. If we loop over them `awaiting` for each one to fulfill, they will execute one after another. In this case we don't need anything else because we already `await` for each script to load anyway. 

```javascript
const urls = ['https://learn.javascript.ru//article/promise-chaining/one.js',
    'https://learn.javascript.ru//article/promise-chaining/two.js',
	'https://learn.javascript.ru/article/promise-chaining/three.js']

async function loadScript(src){
	/*1 s delay is for the indication of how does the outer function run this functino: 
	Consecutively: there'll be 3 s delay generated by 3 function calls. 
	In parallel: there'll be 1 s delay as 3 delays will collapse into one.*/
	await new Promise(res => setTimeout(res, 1000))

	const script = document.createElement('script')
	document.head.append(script)

	try {
		script.src = src
		
		// We create a promise and await for its fulfillment in one way or another
		await new Promise((resolve, reject) => {
			script.onload = () => resolve(script)
			script.onerror = () => reject(new Error(script))
		})
		
	} catch (err) {
		console.warn(err)
	}
}

// alternative solution

// async function loadScript(src) {
// 	/*1 s delay is for the indication of how does the outer function run this functino: 
// 	Consecutively: there'll be 3 s delay generated by 3 function calls. 
// 	In parallel: there'll be 1 s delay as 3 delays will collapse into one.*/
// 	await new Promise(res => setTimeout(res, 1000))

// 	const script = document.createElement('script')

// 	try {
// 		const response = await fetch(src)

// 		if(!response.ok){
// 			throw new Error(`Not 200, ${response.status}`)
// 		}

// 		script.textContent = await response.text()
// 		document.head.append(script)
// 		return script

// 	} catch (err) {
// 		console.warn(err)
// 	}
// }

async function loadAllScripts(urls) {
	// Consecutive:
	for (const value of urls) {
		await loadScript(value)
	}

	// Parallel:
	// return Promise.all(urls.map(url => loadScript(url)))
}

loadAllScripts(urls)
.then(() => {
    one()
    three()
    two()
})
.catch(err => console.warn(err))
```

**NB**: `Array.prototype.map` doesn't work for consecutive calls because it can't `await` for the next call - the function is only designed to be used synchronously, so it just executes all the calls one after another. But it works perfectly when we need **simultanious** calls, making the whole function a lot smaller:

***


### The github avatars task using `async/await`

```javascript
function showHideAvatar(src, hideIn = 3000) {
	const img = document.createElement('img')
	img.src = src
	document.body.prepend(img)
	return new Promise(res => 
		setTimeout(() => {
			document.body.removeChild(document.body.firstChild)
			res(img)
		}, hideIn)
	)
}

const url = 'https://api.github.com/users/'
const names = [`mkbaranovskyi`, `kravich13`, `saadflkjxcvogi`]

const responses = await Promise.allSettled(names.map(name => fetch(url + name)))

const users = await Promise.allSettled(responses.map(user => {
	if(user.status === 'fulfilled'){
		return user.value.json()
	}
	alert(`Error! ${user}`)
}))

console.log(users)

await Promise.allSettled(users.map(user => showHideAvatar(user.value.avatar_url)))

alert('The end!')
```
***


### https://learn.javascript.ru/async-await#perepishite-ispolzuya-async-await

```javascript
async function loadJson(url){
	const response = await fetch(url)
	
	if(response.status === 200){
		return await response.json()
	}
	
	throw new Error(response.status)
}

loadJson('no-such-user.json')
.catch(console.log)
```
***


### https://learn.javascript.ru/async-await#perepishite-ispolzuya-async-await

```javascript
class HttpError extends Error {
	constructor(response) {
		super(`${response.status} for ${response.url}`)
		this.name = 'HttpError'
		this.response = response
	}
}

async function loadJson(url) {
	const response = await fetch(url)
	if(response.status === 200){
		return await response.json()
	} else {
		throw new HttpError(response)
	}
}

async function demoGithubUser() {
	while (true) {
		const name = prompt("Enter login", "iliakan")

		try {
			const user = await loadJson(`https://api.github.com/users/${name}`)

			break

		} catch (err) {
			if (err instanceof HttpError && err.response.status === 404) {
				alert("No such user")
				continue
			} else {
				throw err
			}
		}
	}

	alert(`Full name: ${user.name}.`)
	return user
}

demoGithubUser()
```